INFO - CONFIGURATION DESCRIPTION START
INFO - The following configuration was detected:
INFO - uid: 4ea3
INFO - port: 8080
INFO - hop countDEBUG:root:Polling for packet...
DEBUG:root:ILNPSocket Initialised
DEBUG:root:Packet from 2-3 to 0 1 arrived on interface 2
DEBUG:root:Received route request
DEBUG:root:Adding the following path to forwarding table: []
DEBUG:root:Forwarding route request
DEBUG:root:Appending arriving locat21: 19 sends left
route request
DEBUG:root:Flooding packet
DEBUG:root:Forwarding packet to the following locator(s): {6}
DEBUG:root:Polling for packet...
DEBUG:root:Received normal packet from 6-21 for 0 1 on interface None
DEBUG:root:No route found, requesting one.
DEBUG:root:Flooding packet
DEBUG:root:Forwarding packet to the following locator(s): {6}
DEBUG:root:Polling for packet...
DEBUG:root:Packet from 2-3 to 0 1 arrived on interface 2
Exception in thread Thread-1:
Traceback (most recent call last):
  File "/usr/lib64/python3.7/threading.py", line 917, in _bootstrap_inner
    self.run()
  File "/cs/home/jm354/Documents/FourthYear/SH/UCIOT/ilnpsocket/underlay/routing/router.py", line 113, in run
    self.hop_limit - packet.hop_limit)
  File "/cs/home/jm354/Documents/FourthYear/SH/UCIOT/ilnpsocket/underlay/routing/forwardingtable.py", line 41, in record_entry
    if entry.should_be_replaced_by(route_cost):
AttributeError: 'list' object has no attribute 'should_be_replaced_by'

INFO:root:Router failed for some reason?
DEBUG:root:Attempting to gain log file lock
DEBUG:root:Lock obtained
DEBUG:root:Unlocking file
