INFO - CONFIGURATION DESCRIPTION START
INFO - The following configuration was detected:
INFO - uid: 4ea3
INFO - port: 8080
INFO - hop count: DEBUG:root:Polling for packet...
DEBUG:root:ILNPSocket Initialised
DEBUG:root:Packet from 14-39 to 0 1 arrived on interface 10
DEBUG:root:Packet from 14-39 to 0 1 arrived on interface 11
DEBUG:root:Received route request
DEBUG:root:Adding the following path to forwarding table: [14]
Exception in thread Thread-1:
Traceback (most recent call last):
  File "/usr/lib64/python3.7/threading.py", line 917, in _bootstrap_inner
    self.run()
  File "/cs/home/jm354/Documents/FourthYear/SH/UCIOT/ilnpsocket/underlay/routing/router.py", line 116, in run
    self.dsr_service.handle_message(packet, locator_interface)
  File "/cs/home/jm354/Documents/FourthYear/SH/UCIOT/ilnpsocket/underlay/routing/dsrservice.py", line 58, in handle_message
    self.handle_route_request(packet, locator_interface)
  File "/cs/home/jm354/Documents/FourthYear/SH/UCIOT/ilnpsocket/underlay/routing/dsrservice.py", line 65, in handle_route_request
    self.add_path_to_forwarding_table(rreq.locators, arriving_locator)
  File "/cs/home/jm354/Documents/FourthYear/SH/UCIOT/ilnpsocket/underlay/routing/dsrservice.py", line 97, in add_path_to_forwarding_table
    self.forwarding_table.record_entry(locator, arriving_locator, length_of_path)
  File "/cs/home/jm354/Documents/FourthYear/SH/UCIOT/ilnpsocket/underlay/routing/forwardingtable.py", line 41, in record_entry
    if entry.should_be_replaced_by(route_cost):
AttributeError: 'list' object has no attribute 'should_be_replaced_by'

DEBUG:root:Packet from 10-35 to 0 1 arrived on interface 10
DEBUG:root:Packet from 11-36 to 0 1 arrived on interface 11
INFO:root:Router failed for some reason?
DEBUG:root:Attempting to gain log file lock
DEBUG:root:Lock obtained
DEBUG:root:Unlocking file
